<?xml version="1.0" encoding="utf-8"?>
<!-- Converted from MuJoCo so_101.xml -->
<robot name="so101">

  <!-- Materials -->
  <material name="orange">
    <color rgba="1.0 0.331 0.0 1.0"/>
  </material>
  <material name="black">
    <color rgba="0.1 0.1 0.1 1.0"/>
  </material>

  <!-- Link Base -->
  <link name="Base">
    <inertial>
      <origin xyz="0 0 0" rpy="0 0 0"/>
      <mass value="0.147"/>
      <inertia ixx="0.000114686" ixy="-4.59787e-07" ixz="4.97151e-06" iyy="0.000136117" iyz="9.75275e-08" izz="0.000130364"/>
    </inertial>
    <visual>
      <origin xyz="0 0 0" rpy="0 0 0"/>
      <geometry>
        <mesh filename="assets/Base.stl"/>
      </geometry>
      <material name="orange"/>
    </visual>
    <visual>
      <origin xyz="0 0 0" rpy="0 0 0"/>
      <geometry>
        <mesh filename="assets/Base_Motor.stl"/>
      </geometry>
      <material name="black"/>
    </visual>
    <collision>
      <origin xyz="0 0 0" rpy="0 0 0"/>
      <geometry>
        <mesh filename="assets/Base.stl"/>
      </geometry>
    </collision>
  </link>

  <!-- Link Rotation_Pitch -->
  <link name="Rotation_Pitch">
    <inertial>
      <origin xyz="-9.07886e-05 0.0590972 0.031089" rpy="0 0 0"/>
      <mass value="0.119226"/>
      <inertia ixx="5.94278e-05" ixy="0" ixz="0" iyy="5.89975e-05" iyz="0" izz="3.13712e-05"/>
    </inertial>
    <visual>
      <origin xyz="0 0 0" rpy="0 0 0"/>
      <geometry>
        <mesh filename="assets/Rotation_Pitch.stl"/>
      </geometry>
      <material name="orange"/>
    </visual>
    <visual>
      <origin xyz="0 0 0" rpy="0 0 0"/>
      <geometry>
        <mesh filename="assets/Rotation_Pitch_Motor.stl"/>
      </geometry>
      <material name="black"/>
    </visual>
    <collision>
      <origin xyz="0 0 0" rpy="0 0 0"/>
      <geometry>
        <mesh filename="assets/Rotation_Pitch.stl"/>
      </geometry>
    </collision>
  </link>

  <!-- Link Upper_Arm -->
  <link name="Upper_Arm">
    <inertial>
      <origin xyz="-1.72052e-05 0.0701802 0.00310545" rpy="0 0 0"/>
      <mass value="0.162409"/>
      <inertia ixx="0.000213312" ixy="0" ixz="0" iyy="0.000167164" iyz="0" izz="7.01522e-05"/>
    </inertial>
    <visual>
      <origin xyz="0 0 0" rpy="0 0 0"/>
      <geometry>
        <mesh filename="assets/Upper_Arm.stl"/>
      </geometry>
      <material name="orange"/>
    </visual>
    <visual>
      <origin xyz="0 0 0" rpy="0 0 0"/>
      <geometry>
        <mesh filename="assets/Upper_Arm_Motor.stl"/>
      </geometry>
      <material name="black"/>
    </visual>
    <collision>
      <origin xyz="0 0 0" rpy="0 0 0"/>
      <geometry>
        <mesh filename="assets/Upper_Arm.stl"/>
      </geometry>
    </collision>
  </link>

  <!-- Link Lower_Arm -->
  <link name="Lower_Arm">
    <inertial>
      <origin xyz="-0.00339604 0.00137796 0.0768007" rpy="0 0 0"/>
      <mass value="0.147968"/>
      <inertia ixx="0.000138803" ixy="0" ixz="0" iyy="0.000107748" iyz="0" izz="4.84242e-05"/>
    </inertial>
    <visual>
      <origin xyz="0 0 0" rpy="0 0 0"/>
      <geometry>
        <mesh filename="assets/Lower_Arm.stl"/>
      </geometry>
      <material name="orange"/>
    </visual>
    <visual>
      <origin xyz="0 0 0" rpy="0 0 0"/>
      <geometry>
        <mesh filename="assets/Lower_Arm_Motor.stl"/>
      </geometry>
      <material name="black"/>
    </visual>
    <collision>
      <origin xyz="0 0 0" rpy="0 0 0"/>
      <geometry>
        <mesh filename="assets/Lower_Arm.stl"/>
      </geometry>
    </collision>
  </link>

  <!-- Link Wrist_Pitch_Roll -->
  <link name="Wrist_Pitch_Roll">
    <inertial>
      <origin xyz="-0.00852653 -0.0352279 -2.34622e-05" rpy="0 0 0"/>
      <mass value="0.0661321"/>
      <inertia ixx="3.45403e-05" ixy="0" ixz="0" iyy="2.39041e-05" iyz="0" izz="1.94704e-05"/>
    </inertial>
    <visual>
      <origin xyz="0 0 0" rpy="0 0 0"/>
      <geometry>
        <mesh filename="assets/Wrist_Pitch_Roll.stl"/>
      </geometry>
      <material name="orange"/>
    </visual>
    <visual>
      <origin xyz="0 0 0" rpy="0 0 0"/>
      <geometry>
        <mesh filename="assets/Wrist_Pitch_Roll_Motor.stl"/>
      </geometry>
      <material name="black"/>
    </visual>
    <collision>
      <origin xyz="0 0 0" rpy="0 0 0"/>
      <geometry>
        <mesh filename="assets/Wrist_Pitch_Roll.stl"/>
      </geometry>
    </collision>
  </link>

  <!-- Link Fixed_Jaw -->
  <link name="Fixed_Jaw">
    <inertial>
      <origin xyz="0.00552377 -0.0280167 0.000483583" rpy="0 0 0"/>
      <mass value="0.0929859"/>
      <inertia ixx="5.03136e-05" ixy="0" ixz="0" iyy="4.64098e-05" iyz="0" izz="2.72961e-05"/>
    </inertial>
    <visual>
      <origin xyz="0 0 0" rpy="0 0 0"/>
      <geometry>
        <mesh filename="assets/Fixed_Jaw.stl"/>
      </geometry>
      <material name="orange"/>
    </visual>
    <visual>
      <origin xyz="0 0 0" rpy="0 0 0"/>
      <geometry>
        <mesh filename="assets/Fixed_Jaw_Motor.stl"/>
      </geometry>
      <material name="black"/>
    </visual>
    <collision>
      <origin xyz="0 0 0" rpy="0 0 0"/>
      <geometry>
        <mesh filename="assets/Fixed_Jaw_Collision_1.stl"/>
      </geometry>
    </collision>
    <collision>
      <origin xyz="0 0 0" rpy="0 0 0"/>
      <geometry>
        <mesh filename="assets/Fixed_Jaw_Collision_2.stl"/>
      </geometry>
    </collision>
  </link>

  <!-- Link Moving_Jaw -->
  <link name="Moving_Jaw">
    <inertial>
      <origin xyz="-0.00161745 -0.0303473 0.000449646" rpy="0 0 0"/>
      <mass value="0.0202444"/>
      <inertia ixx="1.11265e-05" ixy="0" ixz="0" iyy="8.99651e-06" iyz="0" izz="2.99548e-06"/>
    </inertial>
    <visual>
      <origin xyz="0 0 0" rpy="0 0 0"/>
      <geometry>
        <mesh filename="assets/Moving_Jaw.stl"/>
      </geometry>
      <material name="orange"/>
    </visual>
    <collision>
      <origin xyz="0 0 0" rpy="0 0 0"/>
      <geometry>
        <mesh filename="assets/Moving_Jaw_Collision_1.stl"/>
      </geometry>
    </collision>
    <collision>
      <origin xyz="0 0 0" rpy="0 0 0"/>
      <geometry>
        <mesh filename="assets/Moving_Jaw_Collision_2.stl"/>
      </geometry>
    </collision>
    <collision>
      <origin xyz="0 0 0" rpy="0 0 0"/>
      <geometry>
        <mesh filename="assets/Moving_Jaw_Collision_3.stl"/>
      </geometry>
    </collision>
  </link>

  <!-- Joint: Base to Rotation_Pitch -->
  <joint name="Rotation" type="revolute">
    <origin xyz="0 -0.0452 0.0165" rpy="1.5708 0 0"/>
    <parent link="Base"/>
    <child link="Rotation_Pitch"/>
    <axis xyz="0 1 0"/>
    <limit effort="35" velocity="10" lower="-2.2" upper="2.2"/>
    <dynamics damping="0.1" friction="0.1"/>
  </joint>

  <!-- Joint: Rotation_Pitch to Upper_Arm -->
  <joint name="Pitch" type="revolute">
    <origin xyz="0 0.1025 0.0306" rpy="1.5708 0 0"/>
    <parent link="Rotation_Pitch"/>
    <child link="Upper_Arm"/>
    <axis xyz="1 0 0"/>
    <limit effort="35" velocity="10" lower="-3.14159" upper="0.2"/>
    <dynamics damping="0.1" friction="0.1"/>
  </joint>

  <!-- Joint: Upper_Arm to Lower_Arm -->
  <joint name="Elbow" type="revolute">
    <origin xyz="0 0.11257 0.028" rpy="-1.5708 0 0"/>
    <parent link="Upper_Arm"/>
    <child link="Lower_Arm"/>
    <axis xyz="1 0 0"/>
    <limit effort="35" velocity="10" lower="0" upper="3.14159"/>
    <dynamics damping="0.1" friction="0.1"/>
  </joint>

  <!-- Joint: Lower_Arm to Wrist_Pitch_Roll -->
  <joint name="Wrist_Pitch" type="revolute">
    <origin xyz="0 0.0052 0.1349" rpy="-1.5708 0 0"/>
    <parent link="Lower_Arm"/>
    <child link="Wrist_Pitch_Roll"/>
    <axis xyz="1 0 0"/>
    <limit effort="35" velocity="10" lower="-2.0" upper="1.8"/>
    <dynamics damping="0.1" friction="0.1"/>
  </joint>

  <!-- Joint: Wrist_Pitch_Roll to Fixed_Jaw -->
  <joint name="Wrist_Roll" type="revolute">
    <origin xyz="0 -0.0601 0" rpy="0 1.5708 0"/>
    <parent link="Wrist_Pitch_Roll"/>
    <child link="Fixed_Jaw"/>
    <axis xyz="0 1 0"/>
    <limit effort="35" velocity="10" lower="-3.14159" upper="3.14159"/>
    <dynamics damping="0.1" friction="0.1"/>
  </joint>

  <!-- Joint: Fixed_Jaw to Moving_Jaw -->
  <joint name="Jaw" type="revolute">
    <origin xyz="-0.0202 -0.0244 0" rpy="0 3.14 0"/>
    <parent link="Fixed_Jaw"/>
    <child link="Moving_Jaw"/>
    <axis xyz="0 0 1"/>
    <limit effort="35" velocity="10" lower="-0.2" upper="2.0"/>
    <dynamics damping="0.1" friction="0.1"/>
  </joint>

</robot>
